2023-02-12 19:31:39,760 root INFO Opening D:\_files\#_personal_files\images_26_mars_2022, found 56 files.
2023-02-12 19:31:39,876 root ERROR Traceback (most recent call last):
  File "MoveImagesVideos.py", line 34, in <module>
    with Image.open(image_path) as image:
  File "E:\logiciels\Python\Python38\lib\site-packages\PIL\Image.py", line 3008, in open
    raise UnidentifiedImageError(
PIL.UnidentifiedImageError: cannot identify image file 'D:\\_files\\#_personal_files\\images_26_mars_2022\\VID_20220408_231537.mp4'

2023-02-12 19:31:39,876 root INFO Closing D:\_files\#_personal_files\images_26_mars_2022, 55 files have been moved.
2023-02-12 19:32:34,619 root INFO Opening D:\_files\#_personal_files\images_26_mars_2022, found 56 files.
2023-02-12 19:32:34,744 root ERROR Traceback (most recent call last):
  File "MoveImagesVideos.py", line 34, in <module>
    with Image.open(image_path) as image:
  File "E:\logiciels\Python\Python38\lib\site-packages\PIL\Image.py", line 3008, in open
    raise UnidentifiedImageError(
PIL.UnidentifiedImageError: cannot identify image file 'D:\\_files\\#_personal_files\\images_26_mars_2022\\VID_20220408_231537.mp4'

2023-02-12 19:32:34,744 root INFO Closing D:\_files\#_personal_files\images_26_mars_2022, 55 files have been moved.
2023-02-12 19:33:25,639 root INFO Opening D:\_files\#_personal_files\images_26_mars_2022, found 3 files.
2023-02-12 19:33:25,705 root ERROR Traceback (most recent call last):
  File "MoveImagesVideos.py", line 34, in <module>
    with Image.open(image_path) as image:
  File "E:\logiciels\Python\Python38\lib\site-packages\PIL\Image.py", line 3008, in open
    raise UnidentifiedImageError(
PIL.UnidentifiedImageError: cannot identify image file 'D:\\_files\\#_personal_files\\images_26_mars_2022\\VID_20220408_231537.mp4'

2023-02-12 19:33:25,705 root INFO Closing D:\_files\#_personal_files\images_26_mars_2022, 2 files have been moved.
2023-02-12 19:37:18,782 root INFO Opening D:\_files\#_personal_files\images_26_mars_2022, found 1 files.
2023-02-12 19:37:18,846 root ERROR Traceback (most recent call last):
  File "MoveImagesVideos.py", line 35, in <module>
    with Image.open(image_path) as image:
  File "E:\logiciels\Python\Python38\lib\site-packages\PIL\Image.py", line 3008, in open
    raise UnidentifiedImageError(
PIL.UnidentifiedImageError: cannot identify image file 'D:\\_files\\#_personal_files\\images_26_mars_2022\\VID_20220408_231537.mp4'

2023-02-12 19:37:18,847 root INFO Closing D:\_files\#_personal_files\images_26_mars_2022, 0 files have been moved.
2023-02-12 19:40:44,955 root INFO Opening D:\_files\#_personal_files\IMAGES, found 2964 files.
2023-02-12 19:40:46,214 root ERROR Traceback (most recent call last):
  File "MoveImagesVideos.py", line 35, in <module>
    with Image.open(image_path) as image:
  File "E:\logiciels\Python\Python38\lib\site-packages\PIL\Image.py", line 3008, in open
    raise UnidentifiedImageError(
PIL.UnidentifiedImageError: cannot identify image file 'D:\\_files\\#_personal_files\\IMAGES\\images_12_mai_2022\\VID_20220507_141848.mp4'

2023-02-12 19:40:46,216 root ERROR Traceback (most recent call last):
  File "MoveImagesVideos.py", line 35, in <module>
    with Image.open(image_path) as image:
  File "E:\logiciels\Python\Python38\lib\site-packages\PIL\Image.py", line 3008, in open
    raise UnidentifiedImageError(
PIL.UnidentifiedImageError: cannot identify image file 'D:\\_files\\#_personal_files\\IMAGES\\images_12_mai_2022\\VID_20220507_141948.mp4'

2023-02-12 19:40:46,217 root ERROR Traceback (most recent call last):
  File "MoveImagesVideos.py", line 35, in <module>
    with Image.open(image_path) as image:
  File "E:\logiciels\Python\Python38\lib\site-packages\PIL\Image.py", line 3008, in open
    raise UnidentifiedImageError(
PIL.UnidentifiedImageError: cannot identify image file 'D:\\_files\\#_personal_files\\IMAGES\\images_12_mai_2022\\VID_20220507_142053.mp4'

2023-02-12 19:40:46,219 root ERROR Traceback (most recent call last):
  File "MoveImagesVideos.py", line 35, in <module>
    with Image.open(image_path) as image:
  File "E:\logiciels\Python\Python38\lib\site-packages\PIL\Image.py", line 3008, in open
    raise UnidentifiedImageError(
PIL.UnidentifiedImageError: cannot identify image file 'D:\\_files\\#_personal_files\\IMAGES\\images_12_mai_2022\\VID_20220507_142237.mp4'

2023-02-12 19:40:46,221 root ERROR Traceback (most recent call last):
  File "MoveImagesVideos.py", line 35, in <module>
    with Image.open(image_path) as image:
  File "E:\logiciels\Python\Python38\lib\site-packages\PIL\Image.py", line 3008, in open
    raise UnidentifiedImageError(
PIL.UnidentifiedImageError: cannot identify image file 'D:\\_files\\#_personal_files\\IMAGES\\images_12_mai_2022\\VID_20220507_143102.mp4'

2023-02-12 19:40:46,222 root ERROR Traceback (most recent call last):
  File "MoveImagesVideos.py", line 35, in <module>
    with Image.open(image_path) as image:
  File "E:\logiciels\Python\Python38\lib\site-packages\PIL\Image.py", line 3008, in open
    raise UnidentifiedImageError(
PIL.UnidentifiedImageError: cannot identify image file 'D:\\_files\\#_personal_files\\IMAGES\\images_12_mai_2022\\VID_20220507_143302.mp4'

2023-02-12 19:40:46,223 root ERROR Traceback (most recent call last):
  File "MoveImagesVideos.py", line 35, in <module>
    with Image.open(image_path) as image:
  File "E:\logiciels\Python\Python38\lib\site-packages\PIL\Image.py", line 3008, in open
    raise UnidentifiedImageError(
PIL.UnidentifiedImageError: cannot identify image file 'D:\\_files\\#_personal_files\\IMAGES\\images_12_mai_2022\\VID_20220507_143444.mp4'

2023-02-12 19:40:48,56 root ERROR Traceback (most recent call last):
  File "MoveImagesVideos.py", line 35, in <module>
    with Image.open(image_path) as image:
  File "E:\logiciels\Python\Python38\lib\site-packages\PIL\Image.py", line 3008, in open
    raise UnidentifiedImageError(
PIL.UnidentifiedImageError: cannot identify image file 'D:\\_files\\#_personal_files\\IMAGES\\images_15_juillet_2022\\VID_20220708_175746.mp4'

2023-02-12 19:40:48,60 root ERROR Traceback (most recent call last):
  File "MoveImagesVideos.py", line 51, in <module>
    shutil.move(str(image_path), str(dir_path))
  File "E:\logiciels\Python\Python38\lib\shutil.py", line 786, in move
    raise Error("Destination path '%s' already exists" % real_dst)
shutil.Error: Destination path 'D:\TEMP\2022-01\Screenshot_20220112-144215.jpg' already exists

2023-02-12 19:40:48,61 root ERROR Traceback (most recent call last):
  File "MoveImagesVideos.py", line 51, in <module>
    shutil.move(str(image_path), str(dir_path))
  File "E:\logiciels\Python\Python38\lib\shutil.py", line 786, in move
    raise Error("Destination path '%s' already exists" % real_dst)
shutil.Error: Destination path 'D:\TEMP\2022-01\Screenshot_20220112-145147.jpg' already exists

2023-02-12 19:40:48,63 root ERROR Traceback (most recent call last):
  File "MoveImagesVideos.py", line 51, in <module>
    shutil.move(str(image_path), str(dir_path))
  File "E:\logiciels\Python\Python38\lib\shutil.py", line 786, in move
    raise Error("Destination path '%s' already exists" % real_dst)
shutil.Error: Destination path 'D:\TEMP\2022-01\Screenshot_20220112-150235__01.jpg' already exists

2023-02-12 19:40:48,66 root ERROR Traceback (most recent call last):
  File "MoveImagesVideos.py", line 51, in <module>
    shutil.move(str(image_path), str(dir_path))
  File "E:\logiciels\Python\Python38\lib\shutil.py", line 786, in move
    raise Error("Destination path '%s' already exists" % real_dst)
shutil.Error: Destination path 'D:\TEMP\2022-01\Screenshot_20220112-151001.jpg' already exists

2023-02-12 19:40:48,68 root ERROR Traceback (most recent call last):
  File "MoveImagesVideos.py", line 51, in <module>
    shutil.move(str(image_path), str(dir_path))
  File "E:\logiciels\Python\Python38\lib\shutil.py", line 786, in move
    raise Error("Destination path '%s' already exists" % real_dst)
shutil.Error: Destination path 'D:\TEMP\2022-01\Screenshot_20220112-151950.jpg' already exists

2023-02-12 19:40:48,71 root ERROR Traceback (most recent call last):
  File "MoveImagesVideos.py", line 51, in <module>
    shutil.move(str(image_path), str(dir_path))
  File "E:\logiciels\Python\Python38\lib\shutil.py", line 786, in move
    raise Error("Destination path '%s' already exists" % real_dst)
shutil.Error: Destination path 'D:\TEMP\2022-01\Screenshot_20220112-152157.jpg' already exists

2023-02-12 19:40:48,73 root ERROR Traceback (most recent call last):
  File "MoveImagesVideos.py", line 51, in <module>
    shutil.move(str(image_path), str(dir_path))
  File "E:\logiciels\Python\Python38\lib\shutil.py", line 786, in move
    raise Error("Destination path '%s' already exists" % real_dst)
shutil.Error: Destination path 'D:\TEMP\2022-01\Screenshot_20220112-152538.jpg' already exists

2023-02-12 19:40:48,75 root ERROR Traceback (most recent call last):
  File "MoveImagesVideos.py", line 51, in <module>
    shutil.move(str(image_path), str(dir_path))
  File "E:\logiciels\Python\Python38\lib\shutil.py", line 786, in move
    raise Error("Destination path '%s' already exists" % real_dst)
shutil.Error: Destination path 'D:\TEMP\2022-01\Screenshot_20220112-152542.jpg' already exists

2023-02-12 19:40:48,77 root ERROR Traceback (most recent call last):
  File "MoveImagesVideos.py", line 51, in <module>
    shutil.move(str(image_path), str(dir_path))
  File "E:\logiciels\Python\Python38\lib\shutil.py", line 786, in move
    raise Error("Destination path '%s' already exists" % real_dst)
shutil.Error: Destination path 'D:\TEMP\2022-01\Screenshot_20220112-152549.jpg' already exists

2023-02-12 19:40:48,356 root ERROR Traceback (most recent call last):
  File "MoveImagesVideos.py", line 35, in <module>
    with Image.open(image_path) as image:
  File "E:\logiciels\Python\Python38\lib\site-packages\PIL\Image.py", line 3008, in open
    raise UnidentifiedImageError(
PIL.UnidentifiedImageError: cannot identify image file 'D:\\_files\\#_personal_files\\IMAGES\\images_one_plus_14_fev\\VID_20220101_015351.mp4'

2023-02-12 19:40:48,358 root ERROR Traceback (most recent call last):
  File "MoveImagesVideos.py", line 35, in <module>
    with Image.open(image_path) as image:
  File "E:\logiciels\Python\Python38\lib\site-packages\PIL\Image.py", line 3008, in open
    raise UnidentifiedImageError(
PIL.UnidentifiedImageError: cannot identify image file 'D:\\_files\\#_personal_files\\IMAGES\\images_one_plus_14_fev\\VID_20220101_015354.mp4'

2023-02-12 19:40:48,360 root ERROR Traceback (most recent call last):
  File "MoveImagesVideos.py", line 35, in <module>
    with Image.open(image_path) as image:
  File "E:\logiciels\Python\Python38\lib\site-packages\PIL\Image.py", line 3008, in open
    raise UnidentifiedImageError(
PIL.UnidentifiedImageError: cannot identify image file 'D:\\_files\\#_personal_files\\IMAGES\\images_one_plus_14_fev\\VID_20220101_015425.mp4'

2023-02-12 19:40:48,425 root ERROR Traceback (most recent call last):
  File "MoveImagesVideos.py", line 51, in <module>
    shutil.move(str(image_path), str(dir_path))
  File "E:\logiciels\Python\Python38\lib\shutil.py", line 786, in move
    raise Error("Destination path '%s' already exists" % real_dst)
shutil.Error: Destination path 'D:\TEMP\2021-12\Messenger_creation_4a827d00-8e62-4f79-9c11-a0328463bbf6.jpeg' already exists

2023-02-12 19:40:48,428 root ERROR Traceback (most recent call last):
  File "MoveImagesVideos.py", line 51, in <module>
    shutil.move(str(image_path), str(dir_path))
  File "E:\logiciels\Python\Python38\lib\shutil.py", line 786, in move
    raise Error("Destination path '%s' already exists" % real_dst)
shutil.Error: Destination path 'D:\TEMP\2021-12\received_1060280034796317.jpeg' already exists

2023-02-12 19:40:48,430 root ERROR Traceback (most recent call last):
  File "MoveImagesVideos.py", line 51, in <module>
    shutil.move(str(image_path), str(dir_path))
  File "E:\logiciels\Python\Python38\lib\shutil.py", line 786, in move
    raise Error("Destination path '%s' already exists" % real_dst)
shutil.Error: Destination path 'D:\TEMP\2021-12\received_1107935233281057.jpeg' already exists

2023-02-12 19:40:48,433 root ERROR Traceback (most recent call last):
  File "MoveImagesVideos.py", line 51, in <module>
    shutil.move(str(image_path), str(dir_path))
  File "E:\logiciels\Python\Python38\lib\shutil.py", line 786, in move
    raise Error("Destination path '%s' already exists" % real_dst)
shutil.Error: Destination path 'D:\TEMP\2021-12\received_1533560593689444.gif' already exists

2023-02-12 19:40:48,450 root ERROR Traceback (most recent call last):
  File "MoveImagesVideos.py", line 51, in <module>
    shutil.move(str(image_path), str(dir_path))
  File "E:\logiciels\Python\Python38\lib\shutil.py", line 786, in move
    raise Error("Destination path '%s' already exists" % real_dst)
shutil.Error: Destination path 'D:\TEMP\2022-01\received_478870320286511.jpeg' already exists

2023-02-12 19:40:48,554 root ERROR Traceback (most recent call last):
  File "MoveImagesVideos.py", line 35, in <module>
    with Image.open(image_path) as image:
  File "E:\logiciels\Python\Python38\lib\site-packages\PIL\Image.py", line 3008, in open
    raise UnidentifiedImageError(
PIL.UnidentifiedImageError: cannot identify image file 'D:\\_files\\#_personal_files\\IMAGES\\images_randonnee\\20220424_110331_01.mp4'

2023-02-12 19:40:48,559 root ERROR Traceback (most recent call last):
  File "MoveImagesVideos.py", line 35, in <module>
    with Image.open(image_path) as image:
  File "E:\logiciels\Python\Python38\lib\site-packages\PIL\Image.py", line 3008, in open
    raise UnidentifiedImageError(
PIL.UnidentifiedImageError: cannot identify image file 'D:\\_files\\#_personal_files\\IMAGES\\images_randonnee\\20220424_110331_05.mp4'

2023-02-12 19:40:48,563 root ERROR Traceback (most recent call last):
  File "MoveImagesVideos.py", line 35, in <module>
    with Image.open(image_path) as image:
  File "E:\logiciels\Python\Python38\lib\site-packages\PIL\Image.py", line 3008, in open
    raise UnidentifiedImageError(
PIL.UnidentifiedImageError: cannot identify image file 'D:\\_files\\#_personal_files\\IMAGES\\images_randonnee\\20220424_110331_10.mp4'

2023-02-12 19:40:48,566 root ERROR Traceback (most recent call last):
  File "MoveImagesVideos.py", line 35, in <module>
    with Image.open(image_path) as image:
  File "E:\logiciels\Python\Python38\lib\site-packages\PIL\Image.py", line 3008, in open
    raise UnidentifiedImageError(
PIL.UnidentifiedImageError: cannot identify image file 'D:\\_files\\#_personal_files\\IMAGES\\images_randonnee\\20220424_110331_99.mp4'

2023-02-12 19:40:48,568 root ERROR Traceback (most recent call last):
  File "MoveImagesVideos.py", line 35, in <module>
    with Image.open(image_path) as image:
  File "E:\logiciels\Python\Python38\lib\site-packages\PIL\Image.py", line 3008, in open
    raise UnidentifiedImageError(
PIL.UnidentifiedImageError: cannot identify image file 'D:\\_files\\#_personal_files\\IMAGES\\images_randonnee\\20220424_110630.mp4'

2023-02-12 19:40:48,609 root ERROR Traceback (most recent call last):
  File "MoveImagesVideos.py", line 35, in <module>
    with Image.open(image_path) as image:
  File "E:\logiciels\Python\Python38\lib\site-packages\PIL\Image.py", line 3008, in open
    raise UnidentifiedImageError(
PIL.UnidentifiedImageError: cannot identify image file 'D:\\_files\\#_personal_files\\IMAGES\\images_randonnee\\20220424_113352_01.mp4'

2023-02-12 19:40:48,613 root ERROR Traceback (most recent call last):
  File "MoveImagesVideos.py", line 35, in <module>
    with Image.open(image_path) as image:
  File "E:\logiciels\Python\Python38\lib\site-packages\PIL\Image.py", line 3008, in open
    raise UnidentifiedImageError(
PIL.UnidentifiedImageError: cannot identify image file 'D:\\_files\\#_personal_files\\IMAGES\\images_randonnee\\20220424_113352_04.mp4'

2023-02-12 19:40:48,620 root ERROR Traceback (most recent call last):
  File "MoveImagesVideos.py", line 35, in <module>
    with Image.open(image_path) as image:
  File "E:\logiciels\Python\Python38\lib\site-packages\PIL\Image.py", line 3008, in open
    raise UnidentifiedImageError(
PIL.UnidentifiedImageError: cannot identify image file 'D:\\_files\\#_personal_files\\IMAGES\\images_randonnee\\20220424_113352_09.mp4'

2023-02-12 19:40:48,623 root ERROR Traceback (most recent call last):
  File "MoveImagesVideos.py", line 35, in <module>
    with Image.open(image_path) as image:
  File "E:\logiciels\Python\Python38\lib\site-packages\PIL\Image.py", line 3008, in open
    raise UnidentifiedImageError(
PIL.UnidentifiedImageError: cannot identify image file 'D:\\_files\\#_personal_files\\IMAGES\\images_randonnee\\20220424_113352_99.mp4'

2023-02-12 19:40:48,624 root ERROR Traceback (most recent call last):
  File "MoveImagesVideos.py", line 35, in <module>
    with Image.open(image_path) as image:
  File "E:\logiciels\Python\Python38\lib\site-packages\PIL\Image.py", line 3008, in open
    raise UnidentifiedImageError(
PIL.UnidentifiedImageError: cannot identify image file 'D:\\_files\\#_personal_files\\IMAGES\\images_randonnee\\20220424_113646.mp4'

2023-02-12 19:40:48,625 root ERROR Traceback (most recent call last):
  File "MoveImagesVideos.py", line 35, in <module>
    with Image.open(image_path) as image:
  File "E:\logiciels\Python\Python38\lib\site-packages\PIL\Image.py", line 3008, in open
    raise UnidentifiedImageError(
PIL.UnidentifiedImageError: cannot identify image file 'D:\\_files\\#_personal_files\\IMAGES\\images_randonnee\\20220424_113929_01.mp4'

2023-02-12 19:40:48,631 root ERROR Traceback (most recent call last):
  File "MoveImagesVideos.py", line 35, in <module>
    with Image.open(image_path) as image:
  File "E:\logiciels\Python\Python38\lib\site-packages\PIL\Image.py", line 3008, in open
    raise UnidentifiedImageError(
PIL.UnidentifiedImageError: cannot identify image file 'D:\\_files\\#_personal_files\\IMAGES\\images_randonnee\\20220424_113929_05.mp4'

2023-02-12 19:40:48,639 root ERROR Traceback (most recent call last):
  File "MoveImagesVideos.py", line 35, in <module>
    with Image.open(image_path) as image:
  File "E:\logiciels\Python\Python38\lib\site-packages\PIL\Image.py", line 3008, in open
    raise UnidentifiedImageError(
PIL.UnidentifiedImageError: cannot identify image file 'D:\\_files\\#_personal_files\\IMAGES\\images_randonnee\\20220424_113929_10.mp4'

2023-02-12 19:40:48,641 root ERROR Traceback (most recent call last):
  File "MoveImagesVideos.py", line 35, in <module>
    with Image.open(image_path) as image:
  File "E:\logiciels\Python\Python38\lib\site-packages\PIL\Image.py", line 3008, in open
    raise UnidentifiedImageError(
PIL.UnidentifiedImageError: cannot identify image file 'D:\\_files\\#_personal_files\\IMAGES\\images_randonnee\\20220424_113929_99.mp4'

2023-02-12 19:40:48,642 root ERROR Traceback (most recent call last):
  File "MoveImagesVideos.py", line 35, in <module>
    with Image.open(image_path) as image:
  File "E:\logiciels\Python\Python38\lib\site-packages\PIL\Image.py", line 3008, in open
    raise UnidentifiedImageError(
PIL.UnidentifiedImageError: cannot identify image file 'D:\\_files\\#_personal_files\\IMAGES\\images_randonnee\\20220424_114351_01.mp4'

2023-02-12 19:40:48,647 root ERROR Traceback (most recent call last):
  File "MoveImagesVideos.py", line 35, in <module>
    with Image.open(image_path) as image:
  File "E:\logiciels\Python\Python38\lib\site-packages\PIL\Image.py", line 3008, in open
    raise UnidentifiedImageError(
PIL.UnidentifiedImageError: cannot identify image file 'D:\\_files\\#_personal_files\\IMAGES\\images_randonnee\\20220424_114351_05.mp4'

2023-02-12 19:40:48,655 root ERROR Traceback (most recent call last):
  File "MoveImagesVideos.py", line 35, in <module>
    with Image.open(image_path) as image:
  File "E:\logiciels\Python\Python38\lib\site-packages\PIL\Image.py", line 3008, in open
    raise UnidentifiedImageError(
PIL.UnidentifiedImageError: cannot identify image file 'D:\\_files\\#_personal_files\\IMAGES\\images_randonnee\\20220424_114351_10.mp4'

2023-02-12 19:40:48,658 root ERROR Traceback (most recent call last):
  File "MoveImagesVideos.py", line 35, in <module>
    with Image.open(image_path) as image:
  File "E:\logiciels\Python\Python38\lib\site-packages\PIL\Image.py", line 3008, in open
    raise UnidentifiedImageError(
PIL.UnidentifiedImageError: cannot identify image file 'D:\\_files\\#_personal_files\\IMAGES\\images_randonnee\\20220424_114351_99.mp4'

2023-02-12 19:40:48,675 root ERROR Traceback (most recent call last):
  File "MoveImagesVideos.py", line 35, in <module>
    with Image.open(image_path) as image:
  File "E:\logiciels\Python\Python38\lib\site-packages\PIL\Image.py", line 3008, in open
    raise UnidentifiedImageError(
PIL.UnidentifiedImageError: cannot identify image file 'D:\\_files\\#_personal_files\\IMAGES\\images_randonnee\\20220424_115437_01.mp4'

2023-02-12 19:40:48,680 root ERROR Traceback (most recent call last):
  File "MoveImagesVideos.py", line 35, in <module>
    with Image.open(image_path) as image:
  File "E:\logiciels\Python\Python38\lib\site-packages\PIL\Image.py", line 3008, in open
    raise UnidentifiedImageError(
PIL.UnidentifiedImageError: cannot identify image file 'D:\\_files\\#_personal_files\\IMAGES\\images_randonnee\\20220424_115437_05.mp4'

2023-02-12 19:40:48,682 root ERROR Traceback (most recent call last):
  File "MoveImagesVideos.py", line 35, in <module>
    with Image.open(image_path) as image:
  File "E:\logiciels\Python\Python38\lib\site-packages\PIL\Image.py", line 3008, in open
    raise UnidentifiedImageError(
PIL.UnidentifiedImageError: cannot identify image file 'D:\\_files\\#_personal_files\\IMAGES\\images_randonnee\\20220424_115437_07.mp4'

2023-02-12 19:40:48,683 root ERROR Traceback (most recent call last):
  File "MoveImagesVideos.py", line 35, in <module>
    with Image.open(image_path) as image:
  File "E:\logiciels\Python\Python38\lib\site-packages\PIL\Image.py", line 3008, in open
    raise UnidentifiedImageError(
PIL.UnidentifiedImageError: cannot identify image file 'D:\\_files\\#_personal_files\\IMAGES\\images_randonnee\\20220424_115437_99.mp4'

2023-02-12 19:40:48,689 root ERROR Traceback (most recent call last):
  File "MoveImagesVideos.py", line 35, in <module>
    with Image.open(image_path) as image:
  File "E:\logiciels\Python\Python38\lib\site-packages\PIL\Image.py", line 3008, in open
    raise UnidentifiedImageError(
PIL.UnidentifiedImageError: cannot identify image file 'D:\\_files\\#_personal_files\\IMAGES\\images_randonnee\\20220424_115517_04.mp4'

2023-02-12 19:40:48,693 root ERROR Traceback (most recent call last):
  File "MoveImagesVideos.py", line 35, in <module>
    with Image.open(image_path) as image:
  File "E:\logiciels\Python\Python38\lib\site-packages\PIL\Image.py", line 3008, in open
    raise UnidentifiedImageError(
PIL.UnidentifiedImageError: cannot identify image file 'D:\\_files\\#_personal_files\\IMAGES\\images_randonnee\\20220424_115517_99.mp4'

2023-02-12 19:40:48,703 root ERROR Traceback (most recent call last):
  File "MoveImagesVideos.py", line 35, in <module>
    with Image.open(image_path) as image:
  File "E:\logiciels\Python\Python38\lib\site-packages\PIL\Image.py", line 3008, in open
    raise UnidentifiedImageError(
PIL.UnidentifiedImageError: cannot identify image file 'D:\\_files\\#_personal_files\\IMAGES\\images_randonnee\\20220424_120357_01.mp4'

2023-02-12 19:40:48,710 root ERROR Traceback (most recent call last):
  File "MoveImagesVideos.py", line 35, in <module>
    with Image.open(image_path) as image:
  File "E:\logiciels\Python\Python38\lib\site-packages\PIL\Image.py", line 3008, in open
    raise UnidentifiedImageError(
PIL.UnidentifiedImageError: cannot identify image file 'D:\\_files\\#_personal_files\\IMAGES\\images_randonnee\\20220424_120357_06.mp4'

2023-02-12 19:40:48,711 root ERROR Traceback (most recent call last):
  File "MoveImagesVideos.py", line 35, in <module>
    with Image.open(image_path) as image:
  File "E:\logiciels\Python\Python38\lib\site-packages\PIL\Image.py", line 3008, in open
    raise UnidentifiedImageError(
PIL.UnidentifiedImageError: cannot identify image file 'D:\\_files\\#_personal_files\\IMAGES\\images_randonnee\\20220424_120357_99.mp4'

2023-02-12 19:40:48,760 root ERROR Traceback (most recent call last):
  File "MoveImagesVideos.py", line 35, in <module>
    with Image.open(image_path) as image:
  File "E:\logiciels\Python\Python38\lib\site-packages\PIL\Image.py", line 3008, in open
    raise UnidentifiedImageError(
PIL.UnidentifiedImageError: cannot identify image file 'D:\\_files\\#_personal_files\\IMAGES\\images_randonnee\\20220424_121933_05.mp4'

2023-02-12 19:40:48,762 root ERROR Traceback (most recent call last):
  File "MoveImagesVideos.py", line 35, in <module>
    with Image.open(image_path) as image:
  File "E:\logiciels\Python\Python38\lib\site-packages\PIL\Image.py", line 3008, in open
    raise UnidentifiedImageError(
PIL.UnidentifiedImageError: cannot identify image file 'D:\\_files\\#_personal_files\\IMAGES\\images_randonnee\\20220424_121933_99.mp4'

2023-02-12 19:40:48,793 root ERROR Traceback (most recent call last):
  File "MoveImagesVideos.py", line 35, in <module>
    with Image.open(image_path) as image:
  File "E:\logiciels\Python\Python38\lib\site-packages\PIL\Image.py", line 3008, in open
    raise UnidentifiedImageError(
PIL.UnidentifiedImageError: cannot identify image file 'D:\\_files\\#_personal_files\\IMAGES\\images_randonnee\\20220424_123630_01.mp4'

2023-02-12 19:40:48,799 root ERROR Traceback (most recent call last):
  File "MoveImagesVideos.py", line 35, in <module>
    with Image.open(image_path) as image:
  File "E:\logiciels\Python\Python38\lib\site-packages\PIL\Image.py", line 3008, in open
    raise UnidentifiedImageError(
PIL.UnidentifiedImageError: cannot identify image file 'D:\\_files\\#_personal_files\\IMAGES\\images_randonnee\\20220424_123630_05.mp4'

2023-02-12 19:40:48,806 root ERROR Traceback (most recent call last):
  File "MoveImagesVideos.py", line 35, in <module>
    with Image.open(image_path) as image:
  File "E:\logiciels\Python\Python38\lib\site-packages\PIL\Image.py", line 3008, in open
    raise UnidentifiedImageError(
PIL.UnidentifiedImageError: cannot identify image file 'D:\\_files\\#_personal_files\\IMAGES\\images_randonnee\\20220424_123630_10.mp4'

2023-02-12 19:40:48,808 root ERROR Traceback (most recent call last):
  File "MoveImagesVideos.py", line 35, in <module>
    with Image.open(image_path) as image:
  File "E:\logiciels\Python\Python38\lib\site-packages\PIL\Image.py", line 3008, in open
    raise UnidentifiedImageError(
PIL.UnidentifiedImageError: cannot identify image file 'D:\\_files\\#_personal_files\\IMAGES\\images_randonnee\\20220424_123630_99.mp4'

2023-02-12 19:40:48,901 root ERROR Traceback (most recent call last):
  File "MoveImagesVideos.py", line 35, in <module>
    with Image.open(image_path) as image:
  File "E:\logiciels\Python\Python38\lib\site-packages\PIL\Image.py", line 3008, in open
    raise UnidentifiedImageError(
PIL.UnidentifiedImageError: cannot identify image file 'D:\\_files\\#_personal_files\\IMAGES\\images_randonnee\\VID_20220424_113938.mp4'

2023-02-12 19:40:48,903 root ERROR Traceback (most recent call last):
  File "MoveImagesVideos.py", line 35, in <module>
    with Image.open(image_path) as image:
  File "E:\logiciels\Python\Python38\lib\site-packages\PIL\Image.py", line 3008, in open
    raise UnidentifiedImageError(
PIL.UnidentifiedImageError: cannot identify image file 'D:\\_files\\#_personal_files\\IMAGES\\images_randonnee\\VID_20220424_114523.mp4'

2023-02-12 19:40:48,904 root ERROR Traceback (most recent call last):
  File "MoveImagesVideos.py", line 35, in <module>
    with Image.open(image_path) as image:
  File "E:\logiciels\Python\Python38\lib\site-packages\PIL\Image.py", line 3008, in open
    raise UnidentifiedImageError(
PIL.UnidentifiedImageError: cannot identify image file 'D:\\_files\\#_personal_files\\IMAGES\\images_randonnee\\VID_20220424_114616.mp4'

2023-02-12 19:40:48,907 root ERROR Traceback (most recent call last):
  File "MoveImagesVideos.py", line 35, in <module>
    with Image.open(image_path) as image:
  File "E:\logiciels\Python\Python38\lib\site-packages\PIL\Image.py", line 3008, in open
    raise UnidentifiedImageError(
PIL.UnidentifiedImageError: cannot identify image file 'D:\\_files\\#_personal_files\\IMAGES\\images_randonnee\\VID_20220424_114707.mp4'

2023-02-12 19:40:48,909 root ERROR Traceback (most recent call last):
  File "MoveImagesVideos.py", line 35, in <module>
    with Image.open(image_path) as image:
  File "E:\logiciels\Python\Python38\lib\site-packages\PIL\Image.py", line 3008, in open
    raise UnidentifiedImageError(
PIL.UnidentifiedImageError: cannot identify image file 'D:\\_files\\#_personal_files\\IMAGES\\images_randonnee\\VID_20220424_121820.mp4'

2023-02-12 19:40:48,910 root ERROR Traceback (most recent call last):
  File "MoveImagesVideos.py", line 35, in <module>
    with Image.open(image_path) as image:
  File "E:\logiciels\Python\Python38\lib\site-packages\PIL\Image.py", line 3008, in open
    raise UnidentifiedImageError(
PIL.UnidentifiedImageError: cannot identify image file 'D:\\_files\\#_personal_files\\IMAGES\\images_randonnee\\VID_20220424_122606.mp4'

2023-02-12 19:40:48,912 root ERROR Traceback (most recent call last):
  File "MoveImagesVideos.py", line 35, in <module>
    with Image.open(image_path) as image:
  File "E:\logiciels\Python\Python38\lib\site-packages\PIL\Image.py", line 3008, in open
    raise UnidentifiedImageError(
PIL.UnidentifiedImageError: cannot identify image file 'D:\\_files\\#_personal_files\\IMAGES\\images_randonnee\\VID_20220424_130039.mp4'

2023-02-12 19:40:49,807 root ERROR Traceback (most recent call last):
  File "MoveImagesVideos.py", line 35, in <module>
    with Image.open(image_path) as image:
  File "E:\logiciels\Python\Python38\lib\site-packages\PIL\Image.py", line 3008, in open
    raise UnidentifiedImageError(
PIL.UnidentifiedImageError: cannot identify image file 'D:\\_files\\#_personal_files\\IMAGES\\majunga_2021\\RJR_7633.MOV'

2023-02-12 19:40:49,999 root ERROR Traceback (most recent call last):
  File "MoveImagesVideos.py", line 35, in <module>
    with Image.open(image_path) as image:
  File "E:\logiciels\Python\Python38\lib\site-packages\PIL\Image.py", line 3008, in open
    raise UnidentifiedImageError(
PIL.UnidentifiedImageError: cannot identify image file 'D:\\_files\\#_personal_files\\IMAGES\\majunga_2021\\RJR_7963.MOV'

2023-02-12 19:40:50,1 root ERROR Traceback (most recent call last):
  File "MoveImagesVideos.py", line 35, in <module>
    with Image.open(image_path) as image:
  File "E:\logiciels\Python\Python38\lib\site-packages\PIL\Image.py", line 3008, in open
    raise UnidentifiedImageError(
PIL.UnidentifiedImageError: cannot identify image file 'D:\\_files\\#_personal_files\\IMAGES\\majunga_2021\\RJR_7964.MOV'

2023-02-12 19:40:50,103 root INFO Closing D:\_files\#_personal_files\IMAGES, 2896 files have been moved.
2023-02-12 19:47:14,694 root INFO Opening D:\_files\#_personal_files\IMAGES, found 1851 files.
2023-02-12 19:47:14,767 root ERROR Traceback (most recent call last):
  File "MoveImagesVideos.py", line 35, in <module>
    with Image.open(image_path) as image:
  File "E:\logiciels\Python\Python38\lib\site-packages\PIL\Image.py", line 3008, in open
    raise UnidentifiedImageError(
PIL.UnidentifiedImageError: cannot identify image file 'D:\\_files\\#_personal_files\\IMAGES\\2022-03-16-131541098.mp4'

2023-02-12 19:47:14,768 root ERROR Traceback (most recent call last):
  File "MoveImagesVideos.py", line 35, in <module>
    with Image.open(image_path) as image:
  File "E:\logiciels\Python\Python38\lib\site-packages\PIL\Image.py", line 3008, in open
    raise UnidentifiedImageError(
PIL.UnidentifiedImageError: cannot identify image file 'D:\\_files\\#_personal_files\\IMAGES\\2022-03-16-140555343.mp4'

2023-02-12 19:47:14,768 root ERROR Traceback (most recent call last):
  File "MoveImagesVideos.py", line 35, in <module>
    with Image.open(image_path) as image:
  File "E:\logiciels\Python\Python38\lib\site-packages\PIL\Image.py", line 3008, in open
    raise UnidentifiedImageError(
PIL.UnidentifiedImageError: cannot identify image file 'D:\\_files\\#_personal_files\\IMAGES\\2022-03-16-145103508.mp4'

2023-02-12 19:47:14,769 root ERROR Traceback (most recent call last):
  File "MoveImagesVideos.py", line 35, in <module>
    with Image.open(image_path) as image:
  File "E:\logiciels\Python\Python38\lib\site-packages\PIL\Image.py", line 3008, in open
    raise UnidentifiedImageError(
PIL.UnidentifiedImageError: cannot identify image file 'D:\\_files\\#_personal_files\\IMAGES\\2022-03-16-164710976.mp4'

2023-02-12 19:47:14,843 root ERROR Traceback (most recent call last):
  File "MoveImagesVideos.py", line 35, in <module>
    with Image.open(image_path) as image:
  File "E:\logiciels\Python\Python38\lib\site-packages\PIL\Image.py", line 3008, in open
    raise UnidentifiedImageError(
PIL.UnidentifiedImageError: cannot identify image file 'D:\\_files\\#_personal_files\\IMAGES\\VID_20220122_145949.mp4'

2023-02-12 19:47:14,845 root ERROR Traceback (most recent call last):
  File "MoveImagesVideos.py", line 35, in <module>
    with Image.open(image_path) as image:
  File "E:\logiciels\Python\Python38\lib\site-packages\PIL\Image.py", line 3008, in open
    raise UnidentifiedImageError(
PIL.UnidentifiedImageError: cannot identify image file 'D:\\_files\\#_personal_files\\IMAGES\\VID_20220128_130032.mp4'

2023-02-12 19:47:14,847 root ERROR Traceback (most recent call last):
  File "MoveImagesVideos.py", line 35, in <module>
    with Image.open(image_path) as image:
  File "E:\logiciels\Python\Python38\lib\site-packages\PIL\Image.py", line 3008, in open
    raise UnidentifiedImageError(
PIL.UnidentifiedImageError: cannot identify image file 'D:\\_files\\#_personal_files\\IMAGES\\VID_20220128_135704.mp4'

2023-02-12 19:47:14,849 root ERROR Traceback (most recent call last):
  File "MoveImagesVideos.py", line 35, in <module>
    with Image.open(image_path) as image:
  File "E:\logiciels\Python\Python38\lib\site-packages\PIL\Image.py", line 3008, in open
    raise UnidentifiedImageError(
PIL.UnidentifiedImageError: cannot identify image file 'D:\\_files\\#_personal_files\\IMAGES\\VID_20220128_135858.mp4'

2023-02-12 19:47:14,850 root ERROR Traceback (most recent call last):
  File "MoveImagesVideos.py", line 35, in <module>
    with Image.open(image_path) as image:
  File "E:\logiciels\Python\Python38\lib\site-packages\PIL\Image.py", line 3008, in open
    raise UnidentifiedImageError(
PIL.UnidentifiedImageError: cannot identify image file 'D:\\_files\\#_personal_files\\IMAGES\\VID_20220305_174318.mp4'

2023-02-12 19:47:14,852 root ERROR Traceback (most recent call last):
  File "MoveImagesVideos.py", line 35, in <module>
    with Image.open(image_path) as image:
  File "E:\logiciels\Python\Python38\lib\site-packages\PIL\Image.py", line 3008, in open
    raise UnidentifiedImageError(
PIL.UnidentifiedImageError: cannot identify image file 'D:\\_files\\#_personal_files\\IMAGES\\VID_20220311_132144.mp4'

2023-02-12 19:47:14,853 root ERROR Traceback (most recent call last):
  File "MoveImagesVideos.py", line 35, in <module>
    with Image.open(image_path) as image:
  File "E:\logiciels\Python\Python38\lib\site-packages\PIL\Image.py", line 3008, in open
    raise UnidentifiedImageError(
PIL.UnidentifiedImageError: cannot identify image file 'D:\\_files\\#_personal_files\\IMAGES\\VID_20220311_142515.mp4'

2023-02-12 19:47:14,855 root ERROR Traceback (most recent call last):
  File "MoveImagesVideos.py", line 35, in <module>
    with Image.open(image_path) as image:
  File "E:\logiciels\Python\Python38\lib\site-packages\PIL\Image.py", line 3008, in open
    raise UnidentifiedImageError(
PIL.UnidentifiedImageError: cannot identify image file 'D:\\_files\\#_personal_files\\IMAGES\\VID_20220311_142525.mp4'

2023-02-12 19:47:14,856 root ERROR Traceback (most recent call last):
  File "MoveImagesVideos.py", line 35, in <module>
    with Image.open(image_path) as image:
  File "E:\logiciels\Python\Python38\lib\site-packages\PIL\Image.py", line 3008, in open
    raise UnidentifiedImageError(
PIL.UnidentifiedImageError: cannot identify image file 'D:\\_files\\#_personal_files\\IMAGES\\VID_20220325_171658.mp4'

2023-02-12 19:47:14,858 root ERROR Traceback (most recent call last):
  File "MoveImagesVideos.py", line 35, in <module>
    with Image.open(image_path) as image:
  File "E:\logiciels\Python\Python38\lib\site-packages\PIL\Image.py", line 3008, in open
    raise UnidentifiedImageError(
PIL.UnidentifiedImageError: cannot identify image file 'D:\\_files\\#_personal_files\\IMAGES\\VID_20220325_171828.mp4'

2023-02-12 19:47:14,860 root ERROR Traceback (most recent call last):
  File "MoveImagesVideos.py", line 35, in <module>
    with Image.open(image_path) as image:
  File "E:\logiciels\Python\Python38\lib\site-packages\PIL\Image.py", line 3008, in open
    raise UnidentifiedImageError(
PIL.UnidentifiedImageError: cannot identify image file 'D:\\_files\\#_personal_files\\IMAGES\\VID_20220325_172409.mp4'

2023-02-12 19:47:15,270 root ERROR Traceback (most recent call last):
  File "MoveImagesVideos.py", line 35, in <module>
    with Image.open(image_path) as image:
  File "E:\logiciels\Python\Python38\lib\site-packages\PIL\Image.py", line 3008, in open
    raise UnidentifiedImageError(
PIL.UnidentifiedImageError: cannot identify image file 'D:\\_files\\#_personal_files\\IMAGES\\tous_images_one_plus_21_02_2021\\IMG_20191029_144526.dng'

2023-02-12 19:47:16,336 root ERROR Traceback (most recent call last):
  File "MoveImagesVideos.py", line 35, in <module>
    with Image.open(image_path) as image:
  File "E:\logiciels\Python\Python38\lib\site-packages\PIL\Image.py", line 3008, in open
    raise UnidentifiedImageError(
PIL.UnidentifiedImageError: cannot identify image file 'D:\\_files\\#_personal_files\\IMAGES\\tous_images_one_plus_21_02_2021\\IMG_20201213_205115.dng'

2023-02-12 19:47:16,348 root ERROR Traceback (most recent call last):
  File "MoveImagesVideos.py", line 35, in <module>
    with Image.open(image_path) as image:
  File "E:\logiciels\Python\Python38\lib\site-packages\PIL\Image.py", line 3008, in open
    raise UnidentifiedImageError(
PIL.UnidentifiedImageError: cannot identify image file 'D:\\_files\\#_personal_files\\IMAGES\\tous_images_one_plus_21_02_2021\\IMG_20201213_205123.dng'

2023-02-12 19:47:16,522 root ERROR Traceback (most recent call last):
  File "MoveImagesVideos.py", line 35, in <module>
    with Image.open(image_path) as image:
  File "E:\logiciels\Python\Python38\lib\site-packages\PIL\Image.py", line 3008, in open
    raise UnidentifiedImageError(
PIL.UnidentifiedImageError: cannot identify image file 'D:\\_files\\#_personal_files\\IMAGES\\tous_images_one_plus_21_02_2021\\IMG_20201224_183823.dng'

2023-02-12 19:47:16,526 root ERROR Traceback (most recent call last):
  File "MoveImagesVideos.py", line 35, in <module>
    with Image.open(image_path) as image:
  File "E:\logiciels\Python\Python38\lib\site-packages\PIL\Image.py", line 3008, in open
    raise UnidentifiedImageError(
PIL.UnidentifiedImageError: cannot identify image file 'D:\\_files\\#_personal_files\\IMAGES\\tous_images_one_plus_21_02_2021\\IMG_20201224_183828.dng'

2023-02-12 19:47:17,161 root ERROR Traceback (most recent call last):
  File "MoveImagesVideos.py", line 51, in <module>
    shutil.move(str(image_path), str(dir_path))
  File "E:\logiciels\Python\Python38\lib\shutil.py", line 786, in move
    raise Error("Destination path '%s' already exists" % real_dst)
shutil.Error: Destination path 'D:\TEMP\2021-02\IMG_20210213_160912.jpg' already exists

2023-02-12 19:47:17,162 root ERROR Traceback (most recent call last):
  File "MoveImagesVideos.py", line 51, in <module>
    shutil.move(str(image_path), str(dir_path))
  File "E:\logiciels\Python\Python38\lib\shutil.py", line 786, in move
    raise Error("Destination path '%s' already exists" % real_dst)
shutil.Error: Destination path 'D:\TEMP\2021-02\IMG_20210213_160913.jpg' already exists

2023-02-12 19:47:17,165 root ERROR Traceback (most recent call last):
  File "MoveImagesVideos.py", line 51, in <module>
    shutil.move(str(image_path), str(dir_path))
  File "E:\logiciels\Python\Python38\lib\shutil.py", line 786, in move
    raise Error("Destination path '%s' already exists" % real_dst)
shutil.Error: Destination path 'D:\TEMP\2021-02\IMG_20210213_170621.jpg' already exists

2023-02-12 19:47:17,168 root ERROR Traceback (most recent call last):
  File "MoveImagesVideos.py", line 51, in <module>
    shutil.move(str(image_path), str(dir_path))
  File "E:\logiciels\Python\Python38\lib\shutil.py", line 786, in move
    raise Error("Destination path '%s' already exists" % real_dst)
shutil.Error: Destination path 'D:\TEMP\2021-02\IMG_20210213_170625.jpg' already exists

2023-02-12 19:47:17,170 root ERROR Traceback (most recent call last):
  File "MoveImagesVideos.py", line 51, in <module>
    shutil.move(str(image_path), str(dir_path))
  File "E:\logiciels\Python\Python38\lib\shutil.py", line 786, in move
    raise Error("Destination path '%s' already exists" % real_dst)
shutil.Error: Destination path 'D:\TEMP\2021-02\IMG_20210213_170628.jpg' already exists

2023-02-12 19:47:17,172 root ERROR Traceback (most recent call last):
  File "MoveImagesVideos.py", line 51, in <module>
    shutil.move(str(image_path), str(dir_path))
  File "E:\logiciels\Python\Python38\lib\shutil.py", line 786, in move
    raise Error("Destination path '%s' already exists" % real_dst)
shutil.Error: Destination path 'D:\TEMP\2021-02\IMG_20210213_170636.jpg' already exists

2023-02-12 19:47:17,174 root ERROR Traceback (most recent call last):
  File "MoveImagesVideos.py", line 51, in <module>
    shutil.move(str(image_path), str(dir_path))
  File "E:\logiciels\Python\Python38\lib\shutil.py", line 786, in move
    raise Error("Destination path '%s' already exists" % real_dst)
shutil.Error: Destination path 'D:\TEMP\2021-02\IMG_20210213_170640.jpg' already exists

2023-02-12 19:47:17,176 root ERROR Traceback (most recent call last):
  File "MoveImagesVideos.py", line 51, in <module>
    shutil.move(str(image_path), str(dir_path))
  File "E:\logiciels\Python\Python38\lib\shutil.py", line 786, in move
    raise Error("Destination path '%s' already exists" % real_dst)
shutil.Error: Destination path 'D:\TEMP\2021-02\IMG_20210213_170646.jpg' already exists

2023-02-12 19:47:17,178 root ERROR Traceback (most recent call last):
  File "MoveImagesVideos.py", line 51, in <module>
    shutil.move(str(image_path), str(dir_path))
  File "E:\logiciels\Python\Python38\lib\shutil.py", line 786, in move
    raise Error("Destination path '%s' already exists" % real_dst)
shutil.Error: Destination path 'D:\TEMP\2021-02\IMG_20210213_170659.jpg' already exists

2023-02-12 19:47:17,180 root ERROR Traceback (most recent call last):
  File "MoveImagesVideos.py", line 51, in <module>
    shutil.move(str(image_path), str(dir_path))
  File "E:\logiciels\Python\Python38\lib\shutil.py", line 786, in move
    raise Error("Destination path '%s' already exists" % real_dst)
shutil.Error: Destination path 'D:\TEMP\2021-02\IMG_20210213_170711.jpg' already exists

2023-02-12 19:47:17,181 root ERROR Traceback (most recent call last):
  File "MoveImagesVideos.py", line 51, in <module>
    shutil.move(str(image_path), str(dir_path))
  File "E:\logiciels\Python\Python38\lib\shutil.py", line 786, in move
    raise Error("Destination path '%s' already exists" % real_dst)
shutil.Error: Destination path 'D:\TEMP\2021-02\IMG_20210213_170714.jpg' already exists

2023-02-12 19:47:17,183 root ERROR Traceback (most recent call last):
  File "MoveImagesVideos.py", line 51, in <module>
    shutil.move(str(image_path), str(dir_path))
  File "E:\logiciels\Python\Python38\lib\shutil.py", line 786, in move
    raise Error("Destination path '%s' already exists" % real_dst)
shutil.Error: Destination path 'D:\TEMP\2021-02\IMG_20210213_171158.jpg' already exists

2023-02-12 19:47:17,185 root ERROR Traceback (most recent call last):
  File "MoveImagesVideos.py", line 51, in <module>
    shutil.move(str(image_path), str(dir_path))
  File "E:\logiciels\Python\Python38\lib\shutil.py", line 786, in move
    raise Error("Destination path '%s' already exists" % real_dst)
shutil.Error: Destination path 'D:\TEMP\2021-02\IMG_20210213_171200.jpg' already exists

2023-02-12 19:47:17,187 root ERROR Traceback (most recent call last):
  File "MoveImagesVideos.py", line 51, in <module>
    shutil.move(str(image_path), str(dir_path))
  File "E:\logiciels\Python\Python38\lib\shutil.py", line 786, in move
    raise Error("Destination path '%s' already exists" % real_dst)
shutil.Error: Destination path 'D:\TEMP\2021-02\IMG_20210213_171207.jpg' already exists

2023-02-12 19:47:17,189 root ERROR Traceback (most recent call last):
  File "MoveImagesVideos.py", line 51, in <module>
    shutil.move(str(image_path), str(dir_path))
  File "E:\logiciels\Python\Python38\lib\shutil.py", line 786, in move
    raise Error("Destination path '%s' already exists" % real_dst)
shutil.Error: Destination path 'D:\TEMP\2021-02\IMG_20210213_171208.jpg' already exists

2023-02-12 19:47:17,191 root ERROR Traceback (most recent call last):
  File "MoveImagesVideos.py", line 51, in <module>
    shutil.move(str(image_path), str(dir_path))
  File "E:\logiciels\Python\Python38\lib\shutil.py", line 786, in move
    raise Error("Destination path '%s' already exists" % real_dst)
shutil.Error: Destination path 'D:\TEMP\2021-02\IMG_20210213_171211.jpg' already exists

2023-02-12 19:47:17,194 root ERROR Traceback (most recent call last):
  File "MoveImagesVideos.py", line 51, in <module>
    shutil.move(str(image_path), str(dir_path))
  File "E:\logiciels\Python\Python38\lib\shutil.py", line 786, in move
    raise Error("Destination path '%s' already exists" % real_dst)
shutil.Error: Destination path 'D:\TEMP\2021-02\IMG_20210213_171226.jpg' already exists

2023-02-12 19:47:17,196 root ERROR Traceback (most recent call last):
  File "MoveImagesVideos.py", line 51, in <module>
    shutil.move(str(image_path), str(dir_path))
  File "E:\logiciels\Python\Python38\lib\shutil.py", line 786, in move
    raise Error("Destination path '%s' already exists" % real_dst)
shutil.Error: Destination path 'D:\TEMP\2021-02\IMG_20210213_171233.jpg' already exists

2023-02-12 19:47:17,198 root ERROR Traceback (most recent call last):
  File "MoveImagesVideos.py", line 51, in <module>
    shutil.move(str(image_path), str(dir_path))
  File "E:\logiciels\Python\Python38\lib\shutil.py", line 786, in move
    raise Error("Destination path '%s' already exists" % real_dst)
shutil.Error: Destination path 'D:\TEMP\2021-02\IMG_20210213_171239.jpg' already exists

2023-02-12 19:47:17,201 root ERROR Traceback (most recent call last):
  File "MoveImagesVideos.py", line 51, in <module>
    shutil.move(str(image_path), str(dir_path))
  File "E:\logiciels\Python\Python38\lib\shutil.py", line 786, in move
    raise Error("Destination path '%s' already exists" % real_dst)
shutil.Error: Destination path 'D:\TEMP\2021-02\IMG_20210213_171309.jpg' already exists

2023-02-12 19:47:17,203 root ERROR Traceback (most recent call last):
  File "MoveImagesVideos.py", line 51, in <module>
    shutil.move(str(image_path), str(dir_path))
  File "E:\logiciels\Python\Python38\lib\shutil.py", line 786, in move
    raise Error("Destination path '%s' already exists" % real_dst)
shutil.Error: Destination path 'D:\TEMP\2021-02\IMG_20210213_171311.jpg' already exists

2023-02-12 19:47:17,205 root ERROR Traceback (most recent call last):
  File "MoveImagesVideos.py", line 51, in <module>
    shutil.move(str(image_path), str(dir_path))
  File "E:\logiciels\Python\Python38\lib\shutil.py", line 786, in move
    raise Error("Destination path '%s' already exists" % real_dst)
shutil.Error: Destination path 'D:\TEMP\2021-02\IMG_20210213_171324.jpg' already exists

2023-02-12 19:47:17,207 root ERROR Traceback (most recent call last):
  File "MoveImagesVideos.py", line 51, in <module>
    shutil.move(str(image_path), str(dir_path))
  File "E:\logiciels\Python\Python38\lib\shutil.py", line 786, in move
    raise Error("Destination path '%s' already exists" % real_dst)
shutil.Error: Destination path 'D:\TEMP\2021-02\IMG_20210213_171328.jpg' already exists

2023-02-12 19:47:17,209 root ERROR Traceback (most recent call last):
  File "MoveImagesVideos.py", line 51, in <module>
    shutil.move(str(image_path), str(dir_path))
  File "E:\logiciels\Python\Python38\lib\shutil.py", line 786, in move
    raise Error("Destination path '%s' already exists" % real_dst)
shutil.Error: Destination path 'D:\TEMP\2021-02\IMG_20210213_171337.jpg' already exists

2023-02-12 19:47:17,211 root ERROR Traceback (most recent call last):
  File "MoveImagesVideos.py", line 51, in <module>
    shutil.move(str(image_path), str(dir_path))
  File "E:\logiciels\Python\Python38\lib\shutil.py", line 786, in move
    raise Error("Destination path '%s' already exists" % real_dst)
shutil.Error: Destination path 'D:\TEMP\2021-02\IMG_20210213_171346.jpg' already exists

2023-02-12 19:47:17,213 root ERROR Traceback (most recent call last):
  File "MoveImagesVideos.py", line 51, in <module>
    shutil.move(str(image_path), str(dir_path))
  File "E:\logiciels\Python\Python38\lib\shutil.py", line 786, in move
    raise Error("Destination path '%s' already exists" % real_dst)
shutil.Error: Destination path 'D:\TEMP\2021-02\IMG_20210213_171354.jpg' already exists

2023-02-12 19:47:17,215 root ERROR Traceback (most recent call last):
  File "MoveImagesVideos.py", line 51, in <module>
    shutil.move(str(image_path), str(dir_path))
  File "E:\logiciels\Python\Python38\lib\shutil.py", line 786, in move
    raise Error("Destination path '%s' already exists" % real_dst)
shutil.Error: Destination path 'D:\TEMP\2021-02\IMG_20210213_171401.jpg' already exists

2023-02-12 19:47:17,216 root ERROR Traceback (most recent call last):
  File "MoveImagesVideos.py", line 51, in <module>
    shutil.move(str(image_path), str(dir_path))
  File "E:\logiciels\Python\Python38\lib\shutil.py", line 786, in move
    raise Error("Destination path '%s' already exists" % real_dst)
shutil.Error: Destination path 'D:\TEMP\2021-02\IMG_20210213_171412.jpg' already exists

2023-02-12 19:47:17,218 root ERROR Traceback (most recent call last):
  File "MoveImagesVideos.py", line 51, in <module>
    shutil.move(str(image_path), str(dir_path))
  File "E:\logiciels\Python\Python38\lib\shutil.py", line 786, in move
    raise Error("Destination path '%s' already exists" % real_dst)
shutil.Error: Destination path 'D:\TEMP\2021-02\IMG_20210213_171416.jpg' already exists

2023-02-12 19:47:17,220 root ERROR Traceback (most recent call last):
  File "MoveImagesVideos.py", line 51, in <module>
    shutil.move(str(image_path), str(dir_path))
  File "E:\logiciels\Python\Python38\lib\shutil.py", line 786, in move
    raise Error("Destination path '%s' already exists" % real_dst)
shutil.Error: Destination path 'D:\TEMP\2021-02\IMG_20210213_171426.jpg' already exists

2023-02-12 19:47:17,221 root ERROR Traceback (most recent call last):
  File "MoveImagesVideos.py", line 51, in <module>
    shutil.move(str(image_path), str(dir_path))
  File "E:\logiciels\Python\Python38\lib\shutil.py", line 786, in move
    raise Error("Destination path '%s' already exists" % real_dst)
shutil.Error: Destination path 'D:\TEMP\2021-02\IMG_20210213_171432.jpg' already exists

2023-02-12 19:47:17,223 root ERROR Traceback (most recent call last):
  File "MoveImagesVideos.py", line 51, in <module>
    shutil.move(str(image_path), str(dir_path))
  File "E:\logiciels\Python\Python38\lib\shutil.py", line 786, in move
    raise Error("Destination path '%s' already exists" % real_dst)
shutil.Error: Destination path 'D:\TEMP\2021-02\IMG_20210213_171720.jpg' already exists

2023-02-12 19:47:17,224 root ERROR Traceback (most recent call last):
  File "MoveImagesVideos.py", line 51, in <module>
    shutil.move(str(image_path), str(dir_path))
  File "E:\logiciels\Python\Python38\lib\shutil.py", line 786, in move
    raise Error("Destination path '%s' already exists" % real_dst)
shutil.Error: Destination path 'D:\TEMP\2021-02\IMG_20210213_171724.jpg' already exists

2023-02-12 19:47:17,226 root ERROR Traceback (most recent call last):
  File "MoveImagesVideos.py", line 51, in <module>
    shutil.move(str(image_path), str(dir_path))
  File "E:\logiciels\Python\Python38\lib\shutil.py", line 786, in move
    raise Error("Destination path '%s' already exists" % real_dst)
shutil.Error: Destination path 'D:\TEMP\2021-02\IMG_20210213_171725.jpg' already exists

2023-02-12 19:47:17,227 root ERROR Traceback (most recent call last):
  File "MoveImagesVideos.py", line 51, in <module>
    shutil.move(str(image_path), str(dir_path))
  File "E:\logiciels\Python\Python38\lib\shutil.py", line 786, in move
    raise Error("Destination path '%s' already exists" % real_dst)
shutil.Error: Destination path 'D:\TEMP\2021-02\IMG_20210213_171807.jpg' already exists

2023-02-12 19:47:17,230 root ERROR Traceback (most recent call last):
  File "MoveImagesVideos.py", line 51, in <module>
    shutil.move(str(image_path), str(dir_path))
  File "E:\logiciels\Python\Python38\lib\shutil.py", line 786, in move
    raise Error("Destination path '%s' already exists" % real_dst)
shutil.Error: Destination path 'D:\TEMP\2021-02\IMG_20210213_171817.jpg' already exists

2023-02-12 19:47:17,231 root ERROR Traceback (most recent call last):
  File "MoveImagesVideos.py", line 51, in <module>
    shutil.move(str(image_path), str(dir_path))
  File "E:\logiciels\Python\Python38\lib\shutil.py", line 786, in move
    raise Error("Destination path '%s' already exists" % real_dst)
shutil.Error: Destination path 'D:\TEMP\2021-02\IMG_20210213_171822.jpg' already exists

2023-02-12 19:47:17,233 root ERROR Traceback (most recent call last):
  File "MoveImagesVideos.py", line 51, in <module>
    shutil.move(str(image_path), str(dir_path))
  File "E:\logiciels\Python\Python38\lib\shutil.py", line 786, in move
    raise Error("Destination path '%s' already exists" % real_dst)
shutil.Error: Destination path 'D:\TEMP\2021-02\IMG_20210213_171832.jpg' already exists

2023-02-12 19:47:17,235 root ERROR Traceback (most recent call last):
  File "MoveImagesVideos.py", line 51, in <module>
    shutil.move(str(image_path), str(dir_path))
  File "E:\logiciels\Python\Python38\lib\shutil.py", line 786, in move
    raise Error("Destination path '%s' already exists" % real_dst)
shutil.Error: Destination path 'D:\TEMP\2021-02\IMG_20210213_171834.jpg' already exists

2023-02-12 19:47:17,238 root ERROR Traceback (most recent call last):
  File "MoveImagesVideos.py", line 51, in <module>
    shutil.move(str(image_path), str(dir_path))
  File "E:\logiciels\Python\Python38\lib\shutil.py", line 786, in move
    raise Error("Destination path '%s' already exists" % real_dst)
shutil.Error: Destination path 'D:\TEMP\2021-02\IMG_20210213_221914.jpg' already exists

2023-02-12 19:47:17,239 root ERROR Traceback (most recent call last):
  File "MoveImagesVideos.py", line 51, in <module>
    shutil.move(str(image_path), str(dir_path))
  File "E:\logiciels\Python\Python38\lib\shutil.py", line 786, in move
    raise Error("Destination path '%s' already exists" % real_dst)
shutil.Error: Destination path 'D:\TEMP\2021-02\IMG_20210213_221917.jpg' already exists

2023-02-12 19:47:17,241 root ERROR Traceback (most recent call last):
  File "MoveImagesVideos.py", line 51, in <module>
    shutil.move(str(image_path), str(dir_path))
  File "E:\logiciels\Python\Python38\lib\shutil.py", line 786, in move
    raise Error("Destination path '%s' already exists" % real_dst)
shutil.Error: Destination path 'D:\TEMP\2021-02\IMG_20210213_221919.jpg' already exists

2023-02-12 19:47:17,243 root ERROR Traceback (most recent call last):
  File "MoveImagesVideos.py", line 51, in <module>
    shutil.move(str(image_path), str(dir_path))
  File "E:\logiciels\Python\Python38\lib\shutil.py", line 786, in move
    raise Error("Destination path '%s' already exists" % real_dst)
shutil.Error: Destination path 'D:\TEMP\2021-02\IMG_20210213_221946.jpg' already exists

2023-02-12 19:47:17,245 root ERROR Traceback (most recent call last):
  File "MoveImagesVideos.py", line 51, in <module>
    shutil.move(str(image_path), str(dir_path))
  File "E:\logiciels\Python\Python38\lib\shutil.py", line 786, in move
    raise Error("Destination path '%s' already exists" % real_dst)
shutil.Error: Destination path 'D:\TEMP\2021-02\IMG_20210213_221949.jpg' already exists

2023-02-12 19:47:17,295 root INFO Closing D:\_files\#_personal_files\IMAGES, 1787 files have been moved.
